
//Em JavaScript, o bloco try-catch é usado para lidar com erros que podem ocorrer durante a execução do código. Esse mecanismo permite que você capture e trate exceções, garantindo que seu código continue funcionando mesmo se algo der errado. A estrutura de try-catch em JavaScript é muito útil para tornar o código mais robusto e melhorar a experiência do usuário.

//Estrutura Básica do try-catch
//A estrutura básica de try-catch em JavaScript é a seguinte:


try {
    // Código que pode gerar um erro
} catch (erro) {
    // Código para lidar com o erro
} finally {
    // (Opcional) Código que será executado sempre, ocorrendo erro ou não
}
//Partes do Bloco try-catch
//try: É onde colocamos o código que pode potencialmente gerar um erro. Qualquer operação que possa falhar (como acessar uma propriedade de um objeto nulo, executar operações assíncronas, ou acessar um índice fora dos limites de um array) deve ser colocada dentro deste bloco.

//catch: Se algum erro ocorrer no bloco try, a execução do código vai pular para o bloco catch, onde podemos capturar e tratar o erro. Dentro desse bloco, temos acesso ao objeto de erro, que contém detalhes sobre o que aconteceu.

//finally (Opcional): Esse bloco é opcional e, se presente, é executado sempre, independentemente de um erro ter ocorrido ou não. É útil para tarefas de limpeza, como fechar conexões, liberar recursos ou exibir mensagens.

//Exemplo Prático
//Vamos ver um exemplo onde tentamos acessar uma propriedade de um objeto que pode não existir, o que pode gerar um erro.

try {
    let usuario = null; // Objeto nulo
    console.log(usuario.nome); // Tentativa de acessar a propriedade 'nome' de um objeto nulo
} catch (erro) {
    console.log("Erro capturado: " + erro.message);
} finally {
    console.log("Bloco finally executado.");
}
//Explicação do Exemplo
//Bloco try: Tentamos acessar usuario.nome, mas como usuario é null, isso gera um erro (TypeError), pois estamos tentando acessar uma propriedade de um objeto nulo.

//Bloco catch: O erro é capturado no bloco catch, onde imprimimos uma mensagem com erro.message, que contém uma descrição do erro. Aqui, a execução é interrompida no bloco try e passa diretamente para o catch.

//Bloco finally: Independentemente do erro, o bloco finally é executado, exibindo uma mensagem. Este bloco é útil para ações de limpeza, como liberar recursos.

//Exemplo com Funções e Validação
//Um exemplo mais realista poderia envolver uma função que tenta converter uma entrada em número e lança uma exceção se o valor for inválido:

function dividirNumeros(a, b) {
    try {
        if (isNaN(a) || isNaN(b)) {
            throw new Error("Ambos os argumentos devem ser números.");
        }
        if (b === 0) {
            throw new Error("Divisão por zero não é permitida.");
        }
        console.log("Resultado:", a / b);
    } catch (erro) {
        console.log("Erro: " + erro.message);
    } finally {
        console.log("Operação de divisão concluída.");
    }
}

dividirNumeros(10, 0);
dividirNumeros(10, "abc");
//Explicação do Exemplo
//Lançando erros (throw): Aqui usamos o comando throw para lançar manualmente um erro se detectarmos uma entrada inválida. Isso nos permite validar condições específicas e interromper o fluxo de execução para tratamento no catch.

//Tratamento no catch: Quando uma condição inválida é lançada com throw, ela é capturada pelo catch, onde imprimimos a mensagem de erro.

//Bloco finally: Este bloco sempre será executado, então, aqui exibimos uma mensagem de finalização da operação.

//Tratamento de Erros Assíncronos
//No caso de operações assíncronas (como chamadas fetch), o tratamento de erros funciona de forma um pouco diferente, já que o try-catch só captura erros síncronos. Para capturar erros em operações assíncronas, é comum usar try-catch dentro de funções async.

//Exemplo com async/await:

async function buscarDados(url) {
    try {
        let resposta = await fetch(url);
        if (!resposta.ok) {
            throw new Error("Erro ao buscar dados: " + resposta.status);
        }
        let dados = await resposta.json();
        console.log("Dados recebidos:", dados);
    } catch (erro) {
        console.log("Erro capturado:", erro.message);
    } finally {
        console.log("Operação de busca concluída.");
    }
}

buscarDados("https://api.exemplo.com/dados");
//Boas Práticas no Uso de try-catch
//Trate erros específicos: Se possível, trate erros específicos usando diferentes mensagens ou abordagens, tornando o tratamento mais informativo.
//Evite try-catch para controle de fluxo: Use-o apenas para capturar exceções, não como uma estrutura de controle de fluxo comum.
//Registre o erro: Quando apropriado, registre o erro para análise posterior e monitoramento de problemas na aplicação.
//Resumo
//O try-catch em JavaScript é uma ferramenta essencial para lidar com erros de forma controlada. Ele permite que você capture e trate erros sem interromper o fluxo de execução do programa, melhorando a robustez e a experiência do usuário.

